<?xml version="1.0" encoding="UTF-8"?>
<testng-results skipped="0" failed="3" ignored="0" total="3" passed="0">
  <reporter-output>
  </reporter-output>
  <suite name="Default suite" duration-ms="37" started-at="2018-02-16T16:41:27Z" finished-at="2018-02-16T16:41:27Z">
    <groups>
    </groups>
    <test name="Default test" duration-ms="37" started-at="2018-02-16T16:41:27Z" finished-at="2018-02-16T16:41:27Z">
      <class name="Wrapper_Act_Test.ExercisePart1Test">
        <test-method status="FAIL" signature="FiveNumbersForTestingTest(java.lang.Double, java.lang.Double, [Ljava.lang.Double;)[pri:0, instance:Wrapper_Act_Test.ExercisePart1Test@523884b2]" name="FiveNumbersForTestingTest" duration-ms="15" started-at="2018-02-16T16:41:27Z" data-provider="data" finished-at="2018-02-16T16:41:27Z">
          <params>
            <param index="0">
              <value>
                <![CDATA[22.0]]>
              </value>
            </param>
            <param index="1">
              <value>
                <![CDATA[56.0]]>
              </value>
            </param>
            <param index="2">
              <value>
                <![CDATA[[Ljava.lang.Double;@6895a785]]>
              </value>
            </param>
          </params>
          <exception class="java.lang.AssertionError">
            <message>
              <![CDATA[
Expected: <192.4>
     but: was <22.0>]]>
            </message>
            <full-stacktrace>
              <![CDATA[java.lang.AssertionError: 
Expected: <192.4>
     but: was <22.0>
at org.hamcrest.MatcherAssert.assertThat(MatcherAssert.java:20)
at org.hamcrest.MatcherAssert.assertThat(MatcherAssert.java:8)
at Wrapper_Act_Test.ExercisePart1Test.FiveNumbersForTestingTest(ExercisePart1Test.java:22)
at sun.reflect.NativeMethodAccessorImpl.invoke0(Native Method)
at sun.reflect.NativeMethodAccessorImpl.invoke(Unknown Source)
at sun.reflect.DelegatingMethodAccessorImpl.invoke(Unknown Source)
at java.lang.reflect.Method.invoke(Unknown Source)
at org.testng.internal.MethodInvocationHelper.invokeMethod(MethodInvocationHelper.java:124)
at org.testng.internal.Invoker.invokeMethod(Invoker.java:580)
at org.testng.internal.Invoker.invokeTestMethod(Invoker.java:716)
at org.testng.internal.Invoker.invokeTestMethods(Invoker.java:988)
at org.testng.internal.TestMethodWorker.invokeTestMethods(TestMethodWorker.java:125)
at org.testng.internal.TestMethodWorker.run(TestMethodWorker.java:109)
at org.testng.TestRunner.privateRun(TestRunner.java:648)
at org.testng.TestRunner.run(TestRunner.java:505)
at org.testng.SuiteRunner.runTest(SuiteRunner.java:455)
at org.testng.SuiteRunner.runSequentially(SuiteRunner.java:450)
at org.testng.SuiteRunner.privateRun(SuiteRunner.java:415)
at org.testng.SuiteRunner.run(SuiteRunner.java:364)
at org.testng.SuiteRunnerWorker.runSuite(SuiteRunnerWorker.java:52)
at org.testng.SuiteRunnerWorker.run(SuiteRunnerWorker.java:84)
at org.testng.TestNG.runSuitesSequentially(TestNG.java:1208)
at org.testng.TestNG.runSuitesLocally(TestNG.java:1137)
at org.testng.TestNG.runSuites(TestNG.java:1049)
at org.testng.TestNG.run(TestNG.java:1017)
at org.testng.remote.AbstractRemoteTestNG.run(AbstractRemoteTestNG.java:114)
at org.testng.remote.RemoteTestNG.initAndRun(RemoteTestNG.java:251)
at org.testng.remote.RemoteTestNG.main(RemoteTestNG.java:77)
]]>
            </full-stacktrace>
          </exception> <!-- java.lang.AssertionError -->
          <reporter-output>
          </reporter-output>
        </test-method> <!-- FiveNumbersForTestingTest -->
        <test-method status="FAIL" signature="FiveNumbersForTestingTest(java.lang.Double, java.lang.Double, [Ljava.lang.Double;)[pri:0, instance:Wrapper_Act_Test.ExercisePart1Test@523884b2]" name="FiveNumbersForTestingTest" duration-ms="0" started-at="2018-02-16T16:41:27Z" data-provider="data" finished-at="2018-02-16T16:41:27Z">
          <params>
            <param index="0">
              <value>
                <![CDATA[2.0]]>
              </value>
            </param>
            <param index="1">
              <value>
                <![CDATA[4.0]]>
              </value>
            </param>
            <param index="2">
              <value>
                <![CDATA[[Ljava.lang.Double;@5a1c0542]]>
              </value>
            </param>
          </params>
          <exception class="java.lang.AssertionError">
            <message>
              <![CDATA[
Expected: <26.6>
     but: was <2.0>]]>
            </message>
            <full-stacktrace>
              <![CDATA[java.lang.AssertionError: 
Expected: <26.6>
     but: was <2.0>
at org.hamcrest.MatcherAssert.assertThat(MatcherAssert.java:20)
at org.hamcrest.MatcherAssert.assertThat(MatcherAssert.java:8)
at Wrapper_Act_Test.ExercisePart1Test.FiveNumbersForTestingTest(ExercisePart1Test.java:22)
at sun.reflect.NativeMethodAccessorImpl.invoke0(Native Method)
at sun.reflect.NativeMethodAccessorImpl.invoke(Unknown Source)
at sun.reflect.DelegatingMethodAccessorImpl.invoke(Unknown Source)
at java.lang.reflect.Method.invoke(Unknown Source)
at org.testng.internal.MethodInvocationHelper.invokeMethod(MethodInvocationHelper.java:124)
at org.testng.internal.Invoker.invokeMethod(Invoker.java:580)
at org.testng.internal.Invoker.invokeTestMethod(Invoker.java:716)
at org.testng.internal.Invoker.invokeTestMethods(Invoker.java:988)
at org.testng.internal.TestMethodWorker.invokeTestMethods(TestMethodWorker.java:125)
at org.testng.internal.TestMethodWorker.run(TestMethodWorker.java:109)
at org.testng.TestRunner.privateRun(TestRunner.java:648)
at org.testng.TestRunner.run(TestRunner.java:505)
at org.testng.SuiteRunner.runTest(SuiteRunner.java:455)
at org.testng.SuiteRunner.runSequentially(SuiteRunner.java:450)
at org.testng.SuiteRunner.privateRun(SuiteRunner.java:415)
at org.testng.SuiteRunner.run(SuiteRunner.java:364)
at org.testng.SuiteRunnerWorker.runSuite(SuiteRunnerWorker.java:52)
at org.testng.SuiteRunnerWorker.run(SuiteRunnerWorker.java:84)
at org.testng.TestNG.runSuitesSequentially(TestNG.java:1208)
at org.testng.TestNG.runSuitesLocally(TestNG.java:1137)
at org.testng.TestNG.runSuites(TestNG.java:1049)
at org.testng.TestNG.run(TestNG.java:1017)
at org.testng.remote.AbstractRemoteTestNG.run(AbstractRemoteTestNG.java:114)
at org.testng.remote.RemoteTestNG.initAndRun(RemoteTestNG.java:251)
at org.testng.remote.RemoteTestNG.main(RemoteTestNG.java:77)
]]>
            </full-stacktrace>
          </exception> <!-- java.lang.AssertionError -->
          <reporter-output>
          </reporter-output>
        </test-method> <!-- FiveNumbersForTestingTest -->
        <test-method status="FAIL" signature="FiveNumbersForTestingTest(java.lang.Double, java.lang.Double, [Ljava.lang.Double;)[pri:0, instance:Wrapper_Act_Test.ExercisePart1Test@523884b2]" name="FiveNumbersForTestingTest" duration-ms="0" started-at="2018-02-16T16:41:27Z" data-provider="data" finished-at="2018-02-16T16:41:27Z">
          <params>
            <param index="0">
              <value>
                <![CDATA[5.0]]>
              </value>
            </param>
            <param index="1">
              <value>
                <![CDATA[5.0]]>
              </value>
            </param>
            <param index="2">
              <value>
                <![CDATA[[Ljava.lang.Double;@1f7030a6]]>
              </value>
            </param>
          </params>
          <exception class="java.lang.AssertionError">
            <message>
              <![CDATA[
Expected: <34.0>
     but: was <5.0>]]>
            </message>
            <full-stacktrace>
              <![CDATA[java.lang.AssertionError: 
Expected: <34.0>
     but: was <5.0>
at org.hamcrest.MatcherAssert.assertThat(MatcherAssert.java:20)
at org.hamcrest.MatcherAssert.assertThat(MatcherAssert.java:8)
at Wrapper_Act_Test.ExercisePart1Test.FiveNumbersForTestingTest(ExercisePart1Test.java:22)
at sun.reflect.NativeMethodAccessorImpl.invoke0(Native Method)
at sun.reflect.NativeMethodAccessorImpl.invoke(Unknown Source)
at sun.reflect.DelegatingMethodAccessorImpl.invoke(Unknown Source)
at java.lang.reflect.Method.invoke(Unknown Source)
at org.testng.internal.MethodInvocationHelper.invokeMethod(MethodInvocationHelper.java:124)
at org.testng.internal.Invoker.invokeMethod(Invoker.java:580)
at org.testng.internal.Invoker.invokeTestMethod(Invoker.java:716)
at org.testng.internal.Invoker.invokeTestMethods(Invoker.java:988)
at org.testng.internal.TestMethodWorker.invokeTestMethods(TestMethodWorker.java:125)
at org.testng.internal.TestMethodWorker.run(TestMethodWorker.java:109)
at org.testng.TestRunner.privateRun(TestRunner.java:648)
at org.testng.TestRunner.run(TestRunner.java:505)
at org.testng.SuiteRunner.runTest(SuiteRunner.java:455)
at org.testng.SuiteRunner.runSequentially(SuiteRunner.java:450)
at org.testng.SuiteRunner.privateRun(SuiteRunner.java:415)
at org.testng.SuiteRunner.run(SuiteRunner.java:364)
at org.testng.SuiteRunnerWorker.runSuite(SuiteRunnerWorker.java:52)
at org.testng.SuiteRunnerWorker.run(SuiteRunnerWorker.java:84)
at org.testng.TestNG.runSuitesSequentially(TestNG.java:1208)
at org.testng.TestNG.runSuitesLocally(TestNG.java:1137)
at org.testng.TestNG.runSuites(TestNG.java:1049)
at org.testng.TestNG.run(TestNG.java:1017)
at org.testng.remote.AbstractRemoteTestNG.run(AbstractRemoteTestNG.java:114)
at org.testng.remote.RemoteTestNG.initAndRun(RemoteTestNG.java:251)
at org.testng.remote.RemoteTestNG.main(RemoteTestNG.java:77)
]]>
            </full-stacktrace>
          </exception> <!-- java.lang.AssertionError -->
          <reporter-output>
          </reporter-output>
        </test-method> <!-- FiveNumbersForTestingTest -->
      </class> <!-- Wrapper_Act_Test.ExercisePart1Test -->
    </test> <!-- Default test -->
  </suite> <!-- Default suite -->
</testng-results>
